Workbook

Sheet CARATULA
B2: PLAN MAESTRO FINANCIERO
B3: GLOBAL EVENT IMPORTS S.A.C.
B5: Evidencia de Aprendizaje 2 (EA2) - Análisis de Viabilidad
B7: INTEGRANTES (100% participación):
B8: Jahir Azael Castillo Paucas
B9: Jostin Alexander Chávez Estela
B10: Marilin Andrea Medina Apolinario
B11: Eric Laureano Mozombite Shishco
B12: María Fernanda Ruiz Luna
B15: Docente: Mg. Jaime Orlando Chávez Tasayco
B16: Sección: 26-2-564P-A
B17: Carrera: Administración y Gestión de Negocios Internacionales
B18: Lima, Perú | Ciclo 2026-II

Sheet PRESENTACION
A1: PRESENTACIÓN - GLOBAL EVENT IMPORTS S.A.C.
B3: DESCRIPCIÓN DEL NEGOCIO
B4: Global Event Imports S.A.C. es una empresa importadora y proveedora de servicios B2B, especializada en el alquiler y la operación de ecosistemas tecnológicos interactivos para eventos sociales y corporativos de alta gama en el Perú.
B8: Modelo de negocio: importamos hardware desde Shenzhen y Guangzhou (China) y lo operamos localmente bajo la modalidad de activos fijos (CAPEX) reusables, reduciendo la merma física (10-15%) característica de la decoración tradicional de eventos.
B12: Mercado objetivo: Wedding Planners y productoras de eventos corporativos, segmento A/B de Lima Metropolitana.
B14: Diferenciales: OTIF 96% - disponibilidad técnica 98% - descarga de contenido digital en menos de 12 segundos - 4 líneas de producto integradas.

Sheet FICHA TECNICA
A1: FICHA TÉCNICA DE PRODUCTOS - GLOBAL EVENT IMPORTS S.A.C.
A3: ATRIBUTO | B3: Línea 1: Glam & Motion (360°) | C3: Línea 2: Interactive Mirror & Tótems | D3: Línea 3: Immersive Booths (LED) | E3: Línea 4: Audio-Guestbooks
A4: Partida Arancelaria | B4: 8479.89.90.00 | C4: 8471.41.00.00 | D4: 8531.20.00.00 | E4: 8519.81.90.00
A5: Descripción Arancelaria | B5: Maquinas y aparatos mecanicos con funcion propia, no expresados en otra parte del capitulo 84 | C5: Maquinas automaticas para tratamiento de datos que incluyan unidad central de tratamiento, unidad de entrada y salida en la misma envoltura | D5: Paneles indicadores con diodos emisores de luz (LED) - Los demas | E5: Aparatos de grabación o reproducción de sonido de soporte semiconductor
A6: Nombre Comercial | B6: Plataforma Giratoria 360° | C6: Espejo Mágico Táctil & Tótem Slim | D6: Cabina Inflable Inmersiva LED | E6: Teléfono Audio-Guestbook Vintage
A7: Marca | B7: Global Event - Glam | C7: Global Event - Mirror | D7: Global Event - Booth | E7: Global Event - Guestbook
A8: Composición | B8: Brazo de acero y fibra de carbono, motor eléctrico de torque constante, adaptador GoPro | C8: Panel táctil LED Slim, espejo templado reflectante, impresora de sublimación térmica | D8: Lona Oxford reforzada, cintas LED RGB direccionables, soplador de aire silencioso | E8: Carcasa de resina vintage, circuito electrónico integrado, micrófono de condensador, tarjeta SD
A9: Condiciones de almacenaje | B9: Almacén seco en Lima, en flight cases reforzados anti-humedad y golpes | C9: Posición vertical en estante acolchado Clase A, fundas protectoras de neopreno | D9: Plegado en bolsas impermeables, libre de humedad e insectos | E9: Caja acolchada individual, evitar campos magnéticos y humedad
A10: Empaque de Importación | B10: Flight Case reforzado con esquinas de aluminio y espuma de alta densidad | C10: Flight Case de madera contrachapada con ruedas y espuma amortiguadora | D10: Caja de cartón corrugado de doble pared con espuma protectora EPE | E10: Caja de cartón reforzado con moldes de espuma EVA
A11: Presentación / Dimensión | B11: Plataforma de 100 cm de diámetro para hasta 4 personas, peso 45 kg | C11: Pantalla de 55 pulgadas táctil interactiva, peso 35 kg | D11: Cabina inflable de 2.5m x 2.5m x 2.5m con soplador interno | E11: Teléfono de mesa modelo retro de 25cm x 15cm x 15cm, peso 1.5 kg
A12: Vida Útil Proyectada | B12: 5 años (60 meses) bajo mantenimiento preventivo semanal | C12: 4 años (48 meses) con calibración periódica de pantalla táctil | D12: 3 años (36 meses) de operación continua (reemplazo de LED si fallan) | E12: 5 años (60 meses) de operación técnica
A13: Certificaciones | B13: CE, RoHS, FCC, ISO 9001 (Proveedor Shenzhen) | C13: CE, RoHS, UL, ISO 9001 (Proveedor Shenzhen) | D13: CE, RoHS, UL, Certificado Ignífugo NFPA 701 | E13: CE, RoHS, FCC
A14: Zonas de Producción | B14: Shenzhen (Guangdong, China) | C14: Shenzhen (Guangdong, China) | D14: Guangzhou (Guangdong, China) | E14: Shenzhen (Guangdong, China)
A15: Régimen de Importación | B15: Mercancía No Restringida (Despacho Anticipado Callao) | C15: Mercancía No Restringida (Despacho Anticipado Callao) | D15: Mercancía No Restringida (Despacho Anticipado Callao) | E15: Mercancía No Restringida (Despacho Anticipado Callao)
A16: Unidades a importar | B16: =INVERSION!B5 -> 1 | C16: =INVERSION!B6 -> 1 | D16: =INVERSION!B7 -> 1 | E16: =INVERSION!B8 -> 1
A18: MARCO REGULATORIO DE IMPORTACIÓN (Entidades Gubernamentales del Perú)
A19: ENTIDAD | B19: COMPETENCIA REGULATORIA SOBRE NUESTROS PRODUCTOS | C19: ENLACE OFICIAL
A20: SUNAT - Aduanas | B20: Clasificación arancelaria y régimen de importación (Despacho Anticipado en el Callao) de los 4 productos. | C20: Arancel SUNAT - Aduanet
A21: MTC - Homologación | B21: Certificado obligatorio para equipos que emiten radiofrecuencia: routers Multi-Carrier, cámaras 360°, espejos y cabinas con WiFi/subida a la nube y audio digital. | C21: MTC - Solicitar homologación
A22: MTC - Consulta de equipos homologados | B22: Verificación en línea de si la marca y modelo del equipo ya cuenta con homologación vigente. | C22: MTC - Consulta de homologados
A23: MINAM - RAEE (D.S. 009-2019-MINAM) | B23: Régimen de gestión de Residuos de Aparatos Eléctricos y Electrónicos; obligaciones del importador de AEE. | C23: MINAM - Régimen RAEE
A24: INDECOPI | B24: Registro de la marca propia (Global Event) y reglamentos técnicos de seguridad de productos eléctricos. | C24: INDECOPI - Registro de marca
A25: VUCE | B25: Ventanilla Única de Comercio Exterior: gestión de la solicitud de homologación MTC y permisos de importación. | C25: VUCE - Comercio Exterior
A28: REFERENCIAS COMERCIALES (Cotización de Proveedores - China)
A29: PRODUCTO | B29: FUENTE | C29: ENLACE
A30: Plataformas 360° | B30: Alibaba - 360 Photo Booth | C30: Ver cotizacion
A31: Espejos Interactivos / Tótems | B31: Alibaba - Smart Mirror Photo Booth | C31: Ver cotizacion
A32: Cabinas LED Inflables | B32: Alibaba - LED Inflatable Photo Booth | C32: Ver cotizacion
A33: Audio-Guestbooks | B33: Alibaba - Audio Guest Book Wedding | C33: Ver cotizacion

Sheet COMPETIDORES
A1: ANÁLISIS DE COMPETIDORES - MERCADO DE EVENTOS PREMIUM (LIMA)
A3: COMPETIDOR | B3: SERVICIOS / LÍNEAS | C3: TICKET REFERENCIAL | D3: FORTALEZA | E3: DEBILIDAD | F3: SITIO WEB
A4: FRK Studio | B4: Photobooth, 360°, fotos con IA, GIFs, photobooth móvil, llaveros (6 experiencias) | C4: Desde S/. 650 (2 h) | D4: +500 eventos, operadores certificados, impresión instantánea, galerías digitales | E4: Enfoque por equipo individual; sin servicio de audio-guestbook | F4: frkstudio.pe
A5: Espacio Digital 360 | B5: iBooth Selfie, Plataforma 360°, Espejo Mágico 65", Tótem (4 equipos, con IA) | C5: Desde S/. 500-750 (2 h, sin IGV) | D5: IA integrada, clientes corporativos (BCP, L'Oréal, Unilever), cumple SCTR | E5: Sin audio-guestbook; competidor directo más fuerte | F5: espaciodigital360.com
A6: Selfie 360 Lima | B6: Plataforma 360° (especializado) | C6: Bajo cotización | D6: Especialización y precio en plataforma 360° | E6: Una sola línea de producto; sin diversificación | F6: selfie360lima.com
A7: Black Moustache | B7: Cabinas de fotos, cabinas 360°, plataformas de video | C7: Bajo cotización | D7: Marca establecida en fotocabinas para eventos | E7: Portafolio limitado a cabinas; sin espejo ni audio | F7: fotocabinasenlima.com.pe
A8: GLOBAL EVENT IMPORTS (Nosotros) | B8: 4 líneas integradas: Glam 360°, Espejo & Tótem, Cabina LED, Audio-Guestbook | C8: Escalonado: S/. 700 (individual) a S/. 2,200 (full) | D8: Oferta escalonada (individual a full); ÚNICO con Audio-Guestbook; modelo B2B integral; OTIF 96%; descarga <12 s | E8: Marca nueva por posicionar en el mercado | F8: (en desarrollo)
A10: Nota: Precios de competidores tomados de sus webs oficiales (jun. 2026), por equipo individual / 2 horas.
A11: Global Event maneja precios escalonados por paquete: Individual S/. 700 | Dúo S/. 1,250 | Trío S/. 1,750 | Full S/. 2,200. Ticket promedio ponderado: ~S/. 1,173 (mix 45/30/15/10, ver PROYECCION DE VENTAS).

Sheet SEGMENTACION
A1: EMBUDO DE SEGMENTACION Y TAMANO DE MERCADO B2B - FUENTES ACTUALIZADAS
A3: CRITERIO DE SEGMENTACION | B3: PORCENTAJE (%) | C3: CANTIDAD | D3: MEDIDA | E3: FUENTE RELEVANTE (LINK DE CONSULTA)
A4: POBLACION DEL PAIS (PERU) | B4: 1 | C4: 34350000 | D4: PERSONAS | E4: INEI - Poblacion y vivienda: https://m.inei.gob.pe/estadisticas/indice-tematico/poblacion-y-vivienda/
A5: NICHO DE MERCADO (LIMA METROPOLITANA) | B5: =C5/C4 -> 0.30370111 | C5: 10432133 | D5: PERSONAS | E5: INEI/Gob.pe - Lima 2025: https://www.gob.pe/institucion/inei/noticias/1087571-lima-supera-los-10-millones-400-mil-habitantes
A6: EDAD OBJETIVO (18 A 64 ANOS - PEA) | B6: 0.65 | C6: =C5*B6 -> 6780886.5 | D6: PERSONAS | E6: INEI - Ocupacion y empleo: https://m.inei.gob.pe/estadisticas/indice-tematico/ocupacion-y-empleo/
A7: NIVEL SOCIOECONOMICO (NSE A/B) | B7: 0.252 | C7: =C6*B7 -> 1708783.4 | D7: PERSONAS | E7: APEIM - NSE Peru: https://apeim.com.pe/
A8: PODER ADQUISITIVO (PEA OCUPADA EN A/B) | B8: 0.957 | C8: =C7*B8 -> 1635305.7 | D8: PERSONAS | E8: INEI - Mercado laboral / PEA: https://m.inei.gob.pe/estadisticas/indice-tematico/ocupacion-y-empleo/
A9: INTERES EN TECNOLOGIA / EVENTOS INTERACTIVOS | B9: 0.15 | C9: =C8*B9 -> 245295.85 | D9: PERSONAS | E9: INEI ENAHO - consumo hogares: https://www.datosabiertos.gob.pe/dataset/encuesta-nacional-de-hogares-enaho-2024-instituto-nacional-de-estad%C3%ADstica-e-inform%C3%A1tica-inei
A10: CONSUMO PER CAPITA DE EVENTOS PREMIUM (ANUAL) | B10: 0.1 | C10: =C9*B10 -> 24529.585 | D10: EVENTOS | E10: Supuesto interno: tasa de conversion anual sobre publico interesado
A11: DEMANDA POTENCIAL DE EVENTOS | C11: =C10 -> 24529.585 | D11: EVENTOS/ANO | E11: Calculado: personas objetivo x consumo anual de eventos premium
A12: PRODUCCION NACIONAL (OFERTA LOCAL DE EVENTOS) | C12: 22400 | D12: EVENTOS/ANO | E12: SUNAT - Operatividad aduanera: https://www.sunat.gob.pe/operatividadaduanera/index.html
A13: IMPORTACION / TECNOLOGIA INTERACTIVA COMPLEMENTARIA | C13: 2500 | D13: EVENTOS/ANO | E13: Trade Map - comercio internacional: https://www.trademap.org/
A14: EXPORTACION / EVENTOS ATENDIDOS FUERA DEL MERCADO OBJETIVO | C14: 1300 | D14: EVENTOS/ANO | E14: Trade Map - servicios/comercio: https://www.trademap.org/
A15: DEMANDA APARENTE (OFERTA TOTAL DISPONIBLE) | C15: =C12+C13-C14 -> 23600 | D15: EVENTOS/ANO | E15: Formula: Produccion + Importacion - Exportacion
A16: DEMANDA INSATISFECHA EN EL MERCADO | C16: =C11-C15 -> 929.5855 | D16: EVENTOS/ANO | E16: Formula: Demanda Potencial - Demanda Aparente
A17: PARTICIPACION REQUERIDA DE GLOBAL EVENT | B17: ='PROYECCION DE VENTAS'!B19/C16 -> 0.153832 | C17: =C16*B17 -> 143 | D17: % SOBRE DEMANDA INSATISFECHA | E17: Formula: Eventos Año 1 / Demanda Insatisfecha; evita market share hardcodeado
A18: UNIDADES A CUBRIR ANUAL (EVENTOS META GLOBAL EVENT) | C18: =ROUND(C17,0) -> 143 | D18: EVENTOS META | E18: Redondeo de eventos meta requerido para calzar con PROYECCION DE VENTAS
A20: PERFIL DEL CLIENTE Y CANALES DE DISTRIBUCION (B2B)
A21: EMPRESA / REPOSITORIO DE EVENTOS | B21: TIPO DE ACTOR | C21: DESCRIPCION COMERCIAL / VALOR DE CANAL | D21: COBERTURA DE MERCADO | E21: ENLACE DE REFERENCIA (LINK DE CONSULTA)
A22: Grace Producciones | B22: Cliente B2B / Canal | C22: Productora de eventos y activaciones corporativas de alta gama. | D22: Nacional / Lima | E22: Grace Producciones: https://graceproducciones.com/
A23: Colmena Producciones | B23: Cliente B2B / Canal | C23: Agencia productora especializada en eventos corporativos y activaciones B2B. | D23: Nacional / Lima | E23: Colmena Producciones: https://colmenaproducciones.com/
A24: Directorio inEventos | B24: Repositorio de Canales | C24: Directorio integral de productoras y organizadoras en Lima Metropolitana. | D24: Lima Metropolitana | E24: inEventos Lima: https://www.ineventos.com/pe/lima
A25: Directorio Ebombo | B25: Repositorio de Canales | C25: Seleccion y analisis de las mejores productoras de eventos en Peru. | D25: Nacional | E25: Ebombo Blog: https://www.ebombo.com/blog/mejores-productoras-de-eventos-en-peru/
A26: Directorio Mercadillo | B26: Repositorio de Canales | C26: Catalogo de empresas de eventos corporativos y activaciones B2B en Lima. | D26: Lima Metropolitana | E26: Mercadillo Peru: https://www.mercadillo.pe/

Sheet C. PRODUCCION
A1: ESTRUCTURA DE COSTO VARIABLE POR SERVICIO - GLOBAL EVENT IMPORTS S.A.C.
A3: A. COSTOS UNITARIOS DE OPERACIÓN
A4: COMPONENTE | B4: APLICACIÓN | C4: COSTO (S/.)
A5: Transporte tercerizado de equipos (van + estiba) | B5: Por evento | C5: 180
A6: Internet móvil Multi-Carrier (router/datos) | B6: Por evento | C6: 30
A7: Consumibles fotográficos (papel térmico, tintas) | B7: Por equipo | C7: 40
A8: Operador técnico de campo (1 por cada 2 equipos) | B8: Por equipo | C8: 60
A9: Costo fijo por evento (movilidad + internet) | C9: =C5+C6 -> 210
A10: Costo incremental por equipo (consumibles + operador) | C10: =C7+C8 -> 100
A12: B. COSTO VARIABLE POR PAQUETE (según número de equipos operados)
A13: PAQUETE | B13: N° EQUIPOS | C13: COSTO FIJO / EVENTO | D13: COSTO POR EQUIPOS | E13: COSTO VARIABLE TOTAL
A14: Individual | B14: 1 | C14: =$C$9 -> 210 | D14: =B14*$C$10 -> 100 | E14: =C14+D14 -> 310
A15: Dúo | B15: 2 | C15: =$C$9 -> 210 | D15: =B15*$C$10 -> 200 | E15: =C15+D15 -> 410
A16: Trío | B16: 3 | C16: =$C$9 -> 210 | D16: =B16*$C$10 -> 300 | E16: =C16+D16 -> 510
A17: Full (4 líneas) | B17: 4 | C17: =$C$9 -> 210 | D17: =B17*$C$10 -> 400 | E17: =C17+D17 -> 610
A19: C. MARGEN DE CONTRIBUCIÓN Y PRECIO POR PAQUETE
A20: PAQUETE | B20: COSTO VARIABLE | C20: PRECIO FIJADO | D20: MARGEN CONTRIB. (S/.) | E20: MARGEN % | F20: MARKUP %
A21: Individual | B21: =E14 -> 310 | C21: 700 | D21: =C21-B21 -> 390 | E21: =D21/C21 -> 0.55714286 | F21: =D21/B21 -> 1.2580645
A22: Dúo | B22: =E15 -> 410 | C22: 1250 | D22: =C22-B22 -> 840 | E22: =D22/C22 -> 0.672 | F22: =D22/B22 -> 2.0487805
A23: Trío | B23: =E16 -> 510 | C23: 1750 | D23: =C23-B23 -> 1240 | E23: =D23/C23 -> 0.70857143 | F23: =D23/B23 -> 2.4313725
A24: Full (4 líneas) | B24: =E17 -> 610 | C24: 2200 | D24: =C24-B24 -> 1590 | E24: =D24/C24 -> 0.72272727 | F24: =D24/B24 -> 2.6065574
A26: D. PROMEDIO PONDERADO SEGÚN MIX DE VENTAS ESPERADO
A27: PAQUETE | B27: MIX % | C27: COSTO VARIABLE | D27: PRECIO | E27: COSTO PONDERADO | F27: PRECIO PONDERADO
A28: Individual | B28: 0.45 | C28: =E14 -> 310 | D28: =C21 -> 700 | E28: =B28*C28 -> 139.5 | F28: =B28*D28 -> 315
A29: Dúo | B29: 0.3 | C29: =E15 -> 410 | D29: =C22 -> 1250 | E29: =B29*C29 -> 123 | F29: =B29*D29 -> 375
A30: Trío | B30: 0.15 | C30: =E16 -> 510 | D30: =C23 -> 1750 | E30: =B30*C30 -> 76.5 | F30: =B30*D30 -> 262.5
A31: Full (4 líneas) | B31: 0.1 | C31: =E17 -> 610 | D31: =C24 -> 2200 | E31: =B31*C31 -> 61 | F31: =B31*D31 -> 220
A32: PROMEDIO PONDERADO | B32: =SUM(B28:B31) -> 1 | E32: =SUM(E28:E31) -> 400 | F32: =SUM(F28:F31) -> 1172.5
E33: * | F33: **
A34: * El COSTO VARIABLE PROMEDIO alimenta el Flujo de Caja.
A35: ** El PRECIO PROMEDIO valida el ticket de Proyección de Ventas.

Sheet G. EXPORT
A1: MATRIZ DE COSTOS DE IMPORTACIÓN (DFI): China -> Almacén Lima
A3: PARÁMETROS TRIBUTARIOS Y CAMBIARIOS
A4: Tipo de cambio (S/. por USD) | B4: =COFACE!B12 -> 3.386 | C4: SUNAT: | D4: https://e-consulta.sunat.gob.pe/cl-at-ittipcam/tcS01Alias
A5: Ad Valorem (arancel s/ CIF) | B5: 0.06
A6: IGV de importación | B6: 0.16
A7: IPM (Impuesto Promoción Municipal) | B7: 0.02
A8: Percepción IGV (adelanto recuperable) | B8: 0.035
A9: Seguro de carga (% del FOB) | B9: 0.01
A11: 1. VALOR FOB DE LA MERCANCÍA (cotización China)
A12: EQUIPO IMPORTADO | B12: CANTIDAD | C12: COTIZACIÓN USD | D12: FOB USD | E12: FOB S/.
A13: Plataforma 360° (Glam & Motion) | B13: =INVERSION!B5 -> 1 | C13: =ANEXOS!C4 -> 1200 | D13: =B13*C13 -> 1200 | E13: =D13*$B$4 -> 4063.2
A14: Espejo Mágico & Tótem | B14: =INVERSION!B6 -> 1 | C14: =ANEXOS!C5 -> 1500 | D14: =B14*C14 -> 1500 | E14: =D14*$B$4 -> 5079
A15: Cabina LED Inmersiva | B15: =INVERSION!B7 -> 1 | C15: =ANEXOS!C6 -> 1800 | D15: =B15*C15 -> 1800 | E15: =D15*$B$4 -> 6094.8
A16: Audio-Guestbook | B16: =INVERSION!B8 -> 1 | C16: =ANEXOS!C7 -> 400 | D16: =B16*C16 -> 400 | E16: =D16*$B$4 -> 1354.4
A17: FOB TOTAL | D17: =SUM(D13:D16) -> 4900 | E17: =SUM(E13:E16) -> 16591.4
A19: 2. COSTOS INTERNACIONALES (FOB -> CIF)
A20: CONCEPTO | D20: MONTO USD | E20: MONTO S/.
A21: Flete marítimo internacional (Shenzhen-Callao) | D21: 1500 | E21: =D21*$B$4 -> 5079
A22: Seguro de carga (% del FOB) | D22: =D17*$B$9 -> 49 | E22: =D22*$B$4 -> 165.914
A23: VALOR CIF (FOB + flete + seguro) | D23: =D17+D21+D22 -> 6449 | E23: =D23*$B$4 -> 21836.314
A25: 3. TRIBUTOS DE IMPORTACIÓN (sobre el valor CIF)
A26: CONCEPTO | D26: MONTO USD | E26: MONTO S/.
A27: Ad Valorem (arancel) | D27: =D23*$B$5 -> 386.94 | E27: =D27*$B$4 -> 1310.1788
A28: IGV de importación (sobre CIF + Ad Valorem) | D28: =(D23+D27)*$B$6 -> 1093.7504 | E28: =D28*$B$4 -> 3703.4389
A29: IPM (sobre CIF + Ad Valorem) | D29: =(D23+D27)*$B$7 -> 136.7188 | E29: =D29*$B$4 -> 462.92986
A30: Percepción IGV (sobre CIF + AV + IGV + IPM) | D30: =(D23+D27+D28+D29)*$B$8 -> 282.32432 | E30: =D30*$B$4 -> 955.95015
A31: TOTAL TRIBUTOS | D31: =SUM(D27:D30) -> 1899.7335 | E31: =D31*$B$4 -> 6432.4977
A33: 4. GASTOS DE NACIONALIZACIÓN Y AGENTE
A34: CONCEPTO | D34: MONTO USD | E34: MONTO S/.
A35: Comisión de agente de aduanas | D35: 400 | E35: =D35*$B$4 -> 1354.4
A36: Gastos portuarios / THC / handling | D36: 350 | E36: =D36*$B$4 -> 1185.1
A37: Almacenaje temporal en depósito | D37: 200 | E37: =D37*$B$4 -> 677.2
A38: Vistos buenos, aforo e inspección | D38: 150 | E38: =D38*$B$4 -> 507.9
A39: TOTAL GASTOS DE NACIONALIZACIÓN | D39: =SUM(D35:D38) -> 1100 | E39: =D39*$B$4 -> 3724.6
A41: 5. TRANSPORTE INTERNO (Callao -> Lima)
A42: Flete local, cuadrilla y posicionamiento | D42: 300 | E42: =D42*$B$4 -> 1015.8
A44: COSTO TOTAL DE IMPORTACIÓN (DDP - puesto en almacén) | D44: =D23+D31+D39+D42 -> 9748.7335 | E44: =D44*$B$4 -> 33009.212
A46: Factor capitalizable neto (DDP sin tributos recuperables / FOB) | D46: =(D44-D48)/D17 -> 1.6808041
A47: Sobrecosto capitalizable neto (% sobre FOB) | D47: =(D44-D48-D17)/D17 -> 0.68080408
A48: Tributos recuperables (IGV + IPM + Percepción) - crédito fiscal | D48: =D28+D29+D30 -> 1512.7935 | E48: =D48*$B$4 -> 5122.3189
...

Sheet CAPITAL DE TRABAJO
A1: CAPITAL DE TRABAJO Y ESTRUCTURA DE FINANCIAMIENTO
A2: A. NECESIDAD DE CAPITAL DE TRABAJO
A3: CONCEPTO | B3: MONTO (S/.) | C3: TIPO | D3: DETALLE / REFERENCIA
A4: Gastos fijos mensuales (administración + ventas) | B4: ='GASTOS ADMINISTRATIVOS'!$B$8+'G. VENTAS'!$B$8 -> 4600 | C4: Cálculo | D4: Suma de gastos fijos mensuales de administración y ventas
A5: Meses de cobertura operativa (reserva de seguridad) | B5: 3 | C5: Dato / Input | D5: Meses de gastos fijos a cubrir para seguridad operativa
A6: Necesidad operativa (mayor entre cobertura y déficit del flujo) | B6: =MAX(B4*B5,-MIN('FLUJO DE CAJA'!B18:M18)) -> 13800 | C6: Cálculo | D6: Protege ante rampa lenta: el mayor entre 3 meses de gastos fijos y el déficit acumulado del flujo operativo
A7: Periodo pre-operativo de importación (jul-oct 2026, sin ingresos) | B7: =('GASTOS ADMINISTRATIVOS'!B5+'GASTOS ADMINISTRATIVOS'!B6+'G. VENTAS'!B8)*4 -> 4800 | C7: Cálculo | D7: 4 meses de almacén + servicios + marketing durante la importación; los 6 socios difieren sueldo hasta iniciar operación
A8: Reserva de contingencia regulatoria (planilla, requisito del proyecto) | B8: 41400 | C8: Dato / Input | D8: Reserva equivalente a planilla y fondo de emergencia (requisito del proyecto)
A9: Presupuesto de formalización (SUNARP) | B9: 800 | C9: Dato / Input | D9: Gastos iniciales notariales y registrales de constitución
A10: Crédito fiscal/percepción recuperable de importación | B10: ='G. EXPORT'!E48 -> 5122.3189 | C10: Cálculo | D10: Tributos recuperables: no se capitalizan; se tratan como crédito fiscal/percepción.
A11: CAPITAL DE TRABAJO REQUERIDO TOTAL | B11: =SUM(B6:B10) -> 65922.319 | C11: Cálculo | D11: Operación, pre-operativo, contingencia, formalización y crédito fiscal recuperable.
A13: B. INVERSIÓN TOTAL A FINANCIAR
A14: Inversión en activos (tangibles + intangibles) | B14: =INVERSION!D18+INVERSION!D36 -> 63832.893
A15: Capital de trabajo requerido | B15: =B11 -> 65922.319
A16: INVERSIÓN TOTAL A FINANCIAR | B16: =B14+B15 -> 129755.21
A18: C. FUENTES DE FINANCIAMIENTO
A19: FUENTE | B19: MONTO (S/.) | C19: PARTICIPACIÓN
A20: Aporte de socios (6 fundadores) | B20: =B16-B21 -> 89755.212 | C20: =B20/$B$16 -> 0.69172722
A21: Préstamo bancario | B21: 40000 | C21: =B21/$B$16 -> 0.30827278
A22: TOTAL FINANCIADO | B22: =B20+B21 -> 129755.21 | C22: =B22/$B$16 -> 1
A23: Aporte por socio (÷6 fundadores) | B23: =B20/6 -> 14959.202
A25: D. CUADRO DE AMORTIZACIÓN DEL PRÉSTAMO
A26: TEA (Tasa Efectiva Anual) | B26: 0.28
A27: Plazo (años) | B27: 3
A28: AÑO | B28: SALDO INICIAL | C28: INTERÉS | D28: AMORTIZACIÓN | E28: CUOTA ANUAL | F28: SALDO FINAL
A29: 1 | B29: =B21 -> 40000 | C29: =B29*$B$26 -> 11200 | D29: =E29-C29 -> 10208.248 | E29: =PMT($B$26,$B$27,-$B$21) -> 21408.248 | F29: =B29-D29 -> 29791.752
A30: 2 | B30: =F29 -> 29791.752 | C30: =B30*$B$26 -> 8341.6905 | D30: =E30-C30 -> 13066.558 | E30: =$E$29 -> 21408.248 | F30: =B30-D30 -> 16725.194
A31: 3 | B31: =F30 -> 16725.194 | C31: =B31*$B$26 -> 4683.0543 | D31: =E31-C31 -> 16725.194 | E31: =$E$29 -> 21408.248 | F31: =B31-D31 -> 0
A32: TOTALES | C32: =SUM(C29:C31) -> 24224.745 | D32: =SUM(D29:D31) -> 40000 | E32: =SUM(E29:E31) -> 64224.745
A34: Nota: El interés del préstamo es un gasto financiero anual; la cuota afecta la liquidez. Ajustar montos y TEA según oferta bancaria real.

Sheet INVERSION
A1: ESTRUCTURA DE INVERSIÓN INICIAL (LEAN - FASE 1) - GLOBAL EVENT IMPORTS S.A.C.
A3: 1. ACTIVOS TANGIBLES (Año 0 / Fase 1)
A4: ACTIVO | B4: CANT | C4: COSTO UNIT. S/. | D4: COSTO TOTAL S/. | E4: VIDA ÚTIL | F4: DEPREC. ANUAL
A5: Plataforma 360° Glam & Motion | B5: 1 | C5: ='G. EXPORT'!C13*'G. EXPORT'!$D$46*'G. EXPORT'!$B$4 -> 6829.4431 | D5: =B5*C5 -> 6829.4431 | E5: 5 | F5: =D5/E5 -> 1365.8886
A6: Espejo Mágico y Tótem | B6: 1 | C6: ='G. EXPORT'!C14*'G. EXPORT'!$D$46*'G. EXPORT'!$B$4 -> 8536.8039 | D6: =B6*C6 -> 8536.8039 | E6: 4 | F6: =D6/E6 -> 2134.201
A7: Cabina LED Inmersiva | B7: 1 | C7: ='G. EXPORT'!C15*'G. EXPORT'!$D$46*'G. EXPORT'!$B$4 -> 10244.165 | D7: =B7*C7 -> 10244.165 | E7: 3 | F7: =D7/E7 -> 3414.7216
A8: Audio-Guestbook | B8: 1 | C8: ='G. EXPORT'!C16*'G. EXPORT'!$D$46*'G. EXPORT'!$B$4 -> 2276.481 | D8: =B8*C8 -> 2276.481 | E8: 5 | F8: =D8/E8 -> 455.29621
A9: Conectividad base y equipos de red (router/NAS) | B9: 1 | C9: 2500 | D9: =B9*C9 -> 2500 | E9: 5 | F9: =D9/E9 -> 500
A10: Escritorios y mobiliario de oficina | B10: 3 | C10: 500 | D10: =B10*C10 -> 1500 | E10: 10 | F10: =D10/E10 -> 150
A11: Sillas y mobiliario complementario | B11: 5 | C11: 150 | D11: =B11*C11 -> 750 | E11: 10 | F11: =D11/E11 -> 75
A12: Computadoras de escritorio | B12: 2 | C12: 2000 | D12: =B12*C12 -> 4000 | E12: 4 | F12: =D12/E12 -> 1000
A13: Laptop gerencial | B13: 1 | C13: 3500 | D13: =B13*C13 -> 3500 | E13: 4 | F13: =D13/E13 -> 875
A14: Impresora multifuncional | B14: 1 | C14: 1200 | D14: =B14*C14 -> 1200 | E14: 4 | F14: =D14/E14 -> 300
A15: Estanterías y racks de almacén (clasif. ABC) | B15: 3 | C15: 900 | D15: =B15*C15 -> 2700 | E15: 10 | F15: =D15/E15 -> 270
A16: Equipos de seguridad y videovigilancia (CCTV) | B16: 1 | C16: 2800 | D16: =B16*C16 -> 2800 | E16: 5 | F16: =D16/E16 -> 560
A17: Kit de herramientas y mantenimiento técnico | B17: 1 | C17: 2000 | D17: =B17*C17 -> 2000 | E17: 3 | F17: =D17/E17 -> 666.66667
A18: SUBTOTAL ACTIVOS TANGIBLES | D18: =SUM(D5:D17) -> 48836.893 | F18: =SUM(F5:F17) -> 11766.774
A20: 2. ACTIVOS INTANGIBLES (Formación de la empresa e inicio de operaciones)
A21: CONCEPTO | B21: ETAPA | D21: VALOR S/. | E21: AMORT. (años) | F21: AMORT. ANUAL
A22: Reserva de nombre (SUNARP) | B22: Formación | D22: 25 | E22: 1 | F22: =D22/E22 -> 25
A23: Elaboración de minuta de constitución | B23: Formación | D23: 350 | E23: 1 | F23: =D23/E23 -> 350
A24: Escritura pública / Notaría | B24: Formación | D24: 450 | E24: 1 | F24: =D24/E24 -> 450
A25: Inscripción en Registros Públicos (SUNARP) | B25: Formación | D25: 90 | E25: 1 | F25: =D25/E25 -> 90
A26: Legalización de libros contables | B26: Formación | D26: 150 | E26: 1 | F26: =D26/E26 -> 150
A27: Registro de marca (INDECOPI) | B27: Formación | D27: 535 | E27: 5 | F27: =D27/E27 -> 107
A28: Licencia de funcionamiento municipal | B28: Operación | D28: 500 | E28: 1 | F28: =D28/E28 -> 500
A29: Certificado ITSE (Defensa Civil) | B29: Operación | D29: 350 | E29: 1 | F29: =D29/E29 -> 350
A30: Registro de importador (Aduanas/VUCE) | B30: Operación | D30: 200 | E30: 1 | F30: =D30/E30 -> 200
A31: Homologación MTC (equipos de RF) | B31: Operación | D31: 346 | E31: 5 | F31: =D31/E31 -> 69.2
A32: Software de gestión y catálogo digital | B32: Operación | D32: 3500 | E32: 5 | F32: =D32/E32 -> 700
A33: Desarrollo web e e-commerce | B33: Operación | D33: 4000 | E33: 3 | F33: =D33/E33 -> 1333.3333
... A35: Gastos pre-operativos (demos y pruebas) | B35: Operación | D35: 2500 | E35: 1 | F35: =D35/E35 -> 2500
A36: SUBTOTAL ACTIVOS INTANGIBLES | D36: =SUM(D22:D35) -> 14996 | F36: =SUM(F22:F35) -> 8824.5333
A38: 3. CAPITAL DE TRABAJO
A39: Capital de trabajo requerido (ver hoja CAPITAL DE TRABAJO) | D39: ='CAPITAL DE TRABAJO'!B11 -> 65922.319
A41: 4. INVERSIÓN INICIAL FASE 1 (AÑO 0)
A42: RUBRO | D42: MONTO S/. | E42: PARTICIPACIÓN
A43: Activos tangibles | D43: =D18 -> 48836.893 | E43: =D43/$D$46 -> 0.37637712
A44: Activos intangibles | D44: =D36 -> 14996 | E44: =D44/$D$46 -> 0.11557147
A45: Capital de trabajo | D45: =D39 -> 65922.319 | E45: =D45/$D$46 -> 0.50805141
...

Sheet PROYECCION DE VENTAS
A1: PROYECCIÓN DE VENTAS — NOV 2026 A OCT 2027 (ESCALONADA POR FASE Y ESTACIONALIDAD)
A3: TICKET PROMEDIO PONDERADO (S/.) | B3: =E33 -> 1172.5
A5: MES | B5: EVENTOS | C5: PRECIO (S/.) | D5: INGRESOS (S/.) | F5: CAPACIDAD/MES | G5: DEMANDA EST. | H5: FASE
A6: Nov 2026 | B6: =MIN(F6,G6) -> 8 | C6: =$B$3 -> 1172.5 | D6: =B6*C6 -> 9380 | F6: =$D$23 -> 8 | G6: 16 | H6: Fase 1
A7: Dic 2026 | B7: =MIN(F7,G7) -> 8 | C7: =$B$3 -> 1172.5 | D7: =B7*C7 -> 9380 | F7: =$D$23 -> 8 | G7: 16 | H7: Fase 1
A8: Ene 2027 | B8: =MIN(F8,G8) -> 7 | C8: =$B$3 -> 1172.5 | D8: =B8*C8 -> 8207.5 | F8: =$D$23 -> 8 | G8: 7 | H8: Fase 1
A9: Feb 2027 | B9: =MIN(F9,G9) -> 8 | C9: =$B$3 -> 1172.5 | D9: =B9*C9 -> 9380 | F9: =$D$23 -> 8 | G9: 8 | H9: Fase 1
A10: Mar 2027 | B10: =MIN(F10,G10) -> 11 | C10: =$B$3 -> 1172.5 | D10: =B10*C10 -> 12897.5 | F10: =$D$24 -> 16 | G10: 11 | H10: Fase 2
A11: Abr 2027 | B11: =MIN(F11,G11) -> 12 | C11: =$B$3 -> 1172.5 | D11: =B11*C11 -> 14070 | F11: =$D$24 -> 16 | G11: 12 | H11: Fase 2
A12: May 2027 | B12: =MIN(F12,G12) -> 15 | C12: =$B$3 -> 1172.5 | D12: =B12*C12 -> 17587.5 | F12: =$D$24 -> 16 | G12: 15 | H12: Fase 2
A13: Jun 2027 | B13: =MIN(F13,G13) -> 14 | C13: =$B$3 -> 1172.5 | D13: =B13*C13 -> 16415 | F13: =$D$24 -> 16 | G13: 14 | H13: Fase 2
A14: Jul 2027 | B14: =MIN(F14,G14) -> 16 | C14: =$B$3 -> 1172.5 | D14: =B14*C14 -> 18760 | F14: =$D$25 -> 16 | G14: 16 | H14: Fase 3
A15: Ago 2027 | B15: =MIN(F15,G15) -> 13 | C15: =$B$3 -> 1172.5 | D15: =B15*C15 -> 15242.5 | F15: =$D$25 -> 16 | G15: 13 | H15: Fase 3
A16: Sep 2027 | B16: =MIN(F16,G16) -> 15 | C16: =$B$3 -> 1172.5 | D16: =B16*C16 -> 17587.5 | F16: =$D$25 -> 16 | G16: 15 | H16: Fase 3
A17: Oct 2027 | B17: =MIN(F17,G17) -> 16 | C17: =$B$3 -> 1172.5 | D17: =B17*C17 -> 18760 | F17: =$D$25 -> 16 | G17: 16 | H17: Fase 3
A19: TOTAL AÑO 1 | B19: =SUM(B6:B17) -> 143 | D19: =SUM(D6:D17) -> 167667.5
A21: CAPACIDAD INSTALADA POR FASE
A22: FASE | B22: MESES | C22: EQUIPOS | D22: EVENTOS/MES MÁX
A23: Fase 1 | B23: Meses 1-4 | C23: 4 | D23: 8
A24: Fase 2 | B24: Meses 5-8 | C24: 8 | D24: 16
A25: Fase 3 | B25: Meses 9-12 | C25: 8 | D25: 16
A27: MIX DE PAQUETES Y TICKET PROMEDIO PONDERADO
A28: PAQUETE | B28: LÍNEAS | C28: PRECIO (S/.) | D28: MIX % | E28: APORTE (S/.)
A29: Individual | B29: 1 | C29: 700 | D29: 0.45 | E29: =C29*D29 -> 315
A30: Dúo | B30: 2 | C30: 1250 | D30: 0.3 | E30: =C30*D30 -> 375
A31: Trío | B31: 3 | C31: 1750 | D31: 0.15 | E31: =C31*D31 -> 262.5
A32: Full | B32: 4 | C32: 2200 | D32: 0.1 | E32: =C32*D32 -> 220
A33: TICKET PROMEDIO PONDERADO | D33: =SUM(D29:D32) -> 1 | E33: =SUM(E29:E32) -> 1172.5
A35: NOTA DE CALENDARIO Y ESTACIONALIDAD (PERÚ)
A36: Año operativo: Nov 2026 – Oct 2027. Los meses Jul-Oct 2026 son pre-operativos (importación, sin ingresos; cubiertos por capital de trabajo).
A37: La demanda refleja estacionalidad limeña: pico en bodas, graduaciones y fin de año (nov-dic); valle en verano/vacaciones (ene-feb); repuntes en Día de la Madre (may) y Fiestas Patrias/graduaciones (jul).
A38: En Fase 1 (nov-feb) la capacidad instalada (8 eventos/mes) TOPA la demanda alta de fin de año: se deja mercado sin atender, lo que justifica la expansión a Fase 2.

Sheet G. VENTAS
A1: GASTOS DE VENTAS Y MARKETING — ESTRATEGIA DIGITAL B2B
A3: A. PRESUPUESTO DE MARKETING (canales y objetivos)
A4: CONCEPTO | B4: MENSUAL (S/.) | C4: ANUAL (S/.) | D4: CANAL / OBJETIVO ESTRATÉGICO
A5: Campañas Google Ads B2B | B5: 500 | C5: =B5*12 -> 6000 | D5: Captación de alta intención: búsquedas "cabina 360", "photobooth", "eventos Lima"
A6: Pauta y contenido en redes sociales | B6: 300 | C6: =B6*12 -> 3600 | D6: Branding: contenido visual de eventos en Instagram, TikTok y Facebook (alta viralidad)
A7: Muestreos y demos en ferias | B7: 0 | C7: =B7*12 -> 0 | D7: Sin participación este año (medida de ahorro de costos)
A8: TOTAL MARKETING / MES | B8: =SUM(B5:B7) -> 800 | C8: =SUM(C5:C7) -> 9600
A10: B. INDICADORES DE EFICIENCIA DE MARKETING
A11: Inversión anual en marketing (S/.) | B11: =C8 -> 9600
A12: Eventos proyectados Año 1 | B12: ='PROYECCION DE VENTAS'!B19 -> 143
A13: CAC — Costo de adquisición por evento (S/.) | B13: =B11/B12 -> 67.132867
A14: Ingresos anuales (S/.) | B14: ='RESUMEN ECONOMICO'!B5 -> 167667.5
A15: Marketing como % de los ingresos | B15: =B11/B14 -> 0.057256177
A16: Ticket promedio por evento (S/.) | B16: ='PROYECCION DE VENTAS'!B3 -> 1172.5
A17: Retorno por evento (ticket ÷ CAC, veces) | B17: =B16/B13 -> 17.465365
A19: Estrategia 100% digital y de bajo costo (sin ferias): captación por búsqueda con intención de compra (Google Ads) + branding visual en redes, donde el contenido de eventos es altamente compartible. El CAC de ~S/.67 por evento frente a un ticket de ~S/.1,173 implica un retorno de ~17x por sol invertido en captación.

Sheet GASTOS ADMINISTRATIVOS
A1: GASTOS ADMINISTRATIVOS — ESTRUCTURA DE COSTOS FIJOS
A3: CONCEPTO | B3: MENSUAL (S/.) | C3: ANUAL (S/.) | D3: NATURALEZA / DETALLE
A4: Nómina de jefaturas (3 socios) | B4: 3000 | C4: =B4*12 -> 36000 | D4: Pro-labore de los 3 socios operativos (S/.1,000 c/u)
A5: Alquiler (se opera desde domicilio de socios) | B5: 0 | C5: =B5*12 -> 0 | D5: Operación desde domicilio: alquiler eliminado (medida de ahorro)
A6: Servicios (luz, agua, internet, teléfono) | B6: 400 | C6: =B6*12 -> 4800 | D6: Servicios básicos de la base de operaciones
A7: Mantenimiento de equipos y repuestos | B7: 400 | C7: =B7*12 -> 4800 | D7: Preventivo, repuestos, almacenamiento en nube y software
A8: TOTAL GASTOS ADMINISTRATIVOS / MES | B8: =SUM(B4:B7) -> 3800 | C8: =SUM(C4:C7) -> 45600
A10: B. INDICADORES DE ESTRUCTURA DE COSTOS FIJOS
A11: Gasto administrativo anual (S/.) | B11: =C8 -> 45600
A12: Gastos fijos totales / mes (admin + ventas) (S/.) | B12: =B8+'G. VENTAS'!B8 -> 4600
A13: Gasto administrativo por evento (S/.) | B13: =C8/'PROYECCION DE VENTAS'!B19 -> 318.88112
A14: Gasto administrativo como % de los ingresos | B14: =C8/'RESUMEN ECONOMICO'!B5 -> 0.27196684
A15: Peso de la nómina en el gasto administrativo | B15: =C4/C8 -> 0.78947368
A17: Estructura de costos fijos optimizada (LEAN): operación desde domicilio de socios (alquiler S/.0) y equipo reducido a 3 socios, sin sacrificar la calidad del servicio. Los gastos fijos totales (S/.4,600/mes) representan una fracción reducida de los ingresos, dando un alto margen de seguridad operativo y un bajo punto de equilibrio.

Sheet FLUJO DE CAJA
A1: ESTADO DE RESULTADOS Y FLUJO DE CAJA PROYECTADO — GLOBAL EVENT IMPORTS S.A.C. (S/.)
A3: CONCEPTO | B3: Nov 2026 | C3: Dic 2026 | D3: Ene 2027 | E3: Feb 2027 | F3: Mar 2027 | G3: Abr 2027 | H3: May 2027 | I3: Jun 2027 | J3: Jul 2027 | K3: Ago 2027 | L3: Sep 2027 | M3: Oct 2027 | O3: TOTAL AÑO 1
A5: INGRESOS
A6: Eventos contratados | B6: ='PROYECCION DE VENTAS'!B6 -> 8 | C6: ='PROYECCION DE VENTAS'!B7 -> 8 | D6: ='PROYECCION DE VENTAS'!B8 -> 7 | E6: ='PROYECCION DE VENTAS'!B9 -> 8 | F6: ='PROYECCION DE VENTAS'!B10 -> 11 | G6: ='PROYECCION DE VENTAS'!B11 -> 12 | H6: ='PROYECCION DE VENTAS'!B12 -> 15 | I6: ='PROYECCION DE VENTAS'!B13 -> 14 | J6: ='PROYECCION DE VENTAS'!B14 -> 16 | K6: ='PROYECCION DE VENTAS'!B15 -> 13 | L6: ='PROYECCION DE VENTAS'!B16 -> 15 | M6: ='PROYECCION DE VENTAS'!B17 -> 16
A7: Ingresos por servicios | B7: ='PROYECCION DE VENTAS'!D6 -> 9380 | C7: ='PROYECCION DE VENTAS'!D7 -> 9380 | D7: ='PROYECCION DE VENTAS'!D8 -> 8207.5 | E7: ='PROYECCION DE VENTAS'!D9 -> 9380 | F7: ='PROYECCION DE VENTAS'!D10 -> 12897.5 | G7: ='PROYECCION DE VENTAS'!D11 -> 14070 | H7: ='PROYECCION DE VENTAS'!D12 -> 17587.5 | I7: ='PROYECCION DE VENTAS'!D13 -> 16415 | J7: ='PROYECCION DE VENTAS'!D14 -> 18760 | K7: ='PROYECCION DE VENTAS'!D15 -> 15242.5 | L7: ='PROYECCION DE VENTAS'!D16 -> 17587.5 | M7: ='PROYECCION DE VENTAS'!D17 -> 18760 | O7: =SUM(B7:M7) -> 167667.5
A9: EGRESOS (ESTADO DE RESULTADOS — incluye depreciación)
A10: Costo variable (eventos x C.V. promedio) | B10: =B6*'C. PRODUCCION'!$E$32 -> 3200 | C10: =C6*'C. PRODUCCION'!$E$32 -> 3200 | D10: =D6*'C. PRODUCCION'!$E$32 -> 2800 | E10: =E6*'C. PRODUCCION'!$E$32 -> 3200 | F10: =F6*'C. PRODUCCION'!$E$32 -> 4400 | G10: =G6*'C. PRODUCCION'!$E$32 -> 4800 | H10: =H6*'C. PRODUCCION'!$E$32 -> 6000 | I10: =I6*'C. PRODUCCION'!$E$32 -> 5600 | ... M10: =M6*'C. PRODUCCION'!$E$32 -> 6400 | O10: =SUM(B10:M10) -> 57200
A11: Gastos administrativos | B11: ='GASTOS ADMINISTRATIVOS'!$B$8 -> 3800 | C11: ='GASTOS ADMINISTRATIVOS'!$B$8 -> 3800 | D11: ='GASTOS ADMINISTRATIVOS'!$B$8 -> 3800 | E11: ='GASTOS ADMINISTRATIVOS'!$B$8 -> 3800 | F11: ='GASTOS ADMINISTRATIVOS'!$B$8 -> 3800 | G11: ='GASTOS ADMINISTRATIVOS'!$B$8 -> 3800 | H11: ='GASTOS ADMINISTRATIVOS'!$B$8 -> 3800 | I11: ='GASTOS ADMINISTRATIVOS'!$B$8 -> 3800 | ... M11: ='GASTOS ADMINISTRATIVOS'!$B$8 -> 3800 | O11: =SUM(B11:M11) -> 45600
A12: Gastos de ventas y marketing | B12: ='G. VENTAS'!$B$8 -> 800 | C12: ='G. VENTAS'!$B$8 -> 800 | D12: ='G. VENTAS'!$B$8 -> 800 | E12: ='G. VENTAS'!$B$8 -> 800 | F12: ='G. VENTAS'!$B$8 -> 800 | G12: ='G. VENTAS'!$B$8 -> 800 | H12: ='G. VENTAS'!$B$8 -> 800 | I12: ='G. VENTAS'!$B$8 -> 800 | ... M12: ='G. VENTAS'!$B$8 -> 800 | O12: =SUM(B12:M12) -> 9600
A13: Depreciación + amortización (activos) | B13: =INVERSION!$D$51 -> 1715.9423 | C13: =INVERSION!$D$51 -> 1715.9423 | D13: =INVERSION!$D$51 -> 1715.9423 | E13: =INVERSION!$D$51 -> 1715.9423 | F13: =INVERSION!$D$51 -> 1715.9423 | G13: =INVERSION!$D$51 -> 1715.9423 | H13: =INVERSION!$D$51 -> 1715.9423 | I13: =INVERSION!$D$51 -> 1715.9423 | ... M13: =INVERSION!$D$51 -> 1715.9423 | O13: =SUM(B13:M13) -> 20591.307
A14: TOTAL EGRESOS | B14: =SUM(B10:B13) -> 9515.9423 | C14: =SUM(C10:C13) -> 9515.9423 | D14: =SUM(D10:D13) -> 9115.9423 | E14: =SUM(E10:E13) -> 9515.9423 | F14: =SUM(F10:F13) -> 10715.942 | G14: =SUM(G10:G13) -> 11115.942 | H14: =SUM(H10:H13) -> 12315.942 | I14: =SUM(I10:I13) -> 11915.942 | ... M14: =SUM(M10:M13) -> 12715.942 | O14: =SUM(B14:M14) -> 132991.31
A16: UTILIDAD OPERATIVA DEL MES (EBIT, antes de financiamiento e impuestos) | B16: =B7-B14 -> -135.94228 | C16: =C7-C14 -> -135.94228 | D16: =D7-D14 -> -908.44228 | E16: =E7-E14 -> -135.94228 | F16: =F7-F14 -> 2181.5577 | G16: =G7-G14 -> 2954.0577 | H16: =H7-H14 -> 5271.5577 | I16: =I7-I14 -> 4499.0577 | ... M16: =M7-M14 -> 6044.0577 | O16: =O7-O14 -> 34676.193
A18: UTILIDAD OPERATIVA ACUMULADA | B18: =B16 -> -135.94228 | C18: =B18+C16 -> -271.88457 | D18: =C18+D16 -> -1180.3268 | E18: =D18+E16 -> -1316.2691 | F18: =E18+F16 -> 865.28859 | G18: =F18+G16 -> 3819.3463 | H18: =G18+H16 -> 9090.904 | I18: =H18+I16 -> 13589.962 | J18: =I18+J16 -> 19634.019 | ... M18: =L18+M16 -> 34676.193
A20: FLUJO DE CAJA FINANCIERO (método indirecto — con servicio de deuda e impuestos)
A21: Utilidad operativa del mes (EBIT) | B21: =B16 -> -135.94228 | C21: =C16 -> -135.94228 | D21: =D16 -> -908.44228 | E21: =E16 -> -135.94228 | F21: =F16 -> 2181.5577 | G21: =G16 -> 2954.0577 | H21: =H16 -> 5271.5577 | I21: =I16 -> 4499.0577 | ... M21: =M16 -> 6044.0577 | O21: =O16 -> 34676.193
A22: (+) Depreciación y amortización (gasto NO-caja) | B22: =B13 -> 1715.9423 | C22: =C13 -> 1715.9423 | D22: =D13 -> 1715.9423 | E22: =E13 -> 1715.9423 | F22: =F13 -> 1715.9423 | G22: =G13 -> 1715.9423 | H22: =H13 -> 1715.9423 | I22: =I13 -> 1715.9423 | ... M22: =M13 -> 1715.9423 | O22: =O13 -> 20591.307
A23: (−) Servicio de deuda (cuota: interés + amortización) | B23: =-'CAPITAL DE TRABAJO'!$E$29/12 -> -1784.0207 | C23: =-'CAPITAL DE TRABAJO'!$E$29/12 -> -1784.0207 | D23: =-'CAPITAL DE TRABAJO'!$E$29/12 -> -1784.0207 | E23: =-'CAPITAL DE TRABAJO'!$E$29/12 -> -1784.0207 | F23: =-'CAPITAL DE TRABAJO'!$E$29/12 -> -1784.0207 | G23: =-'CAPITAL DE TRABAJO'!$E$29/12 -> -1784.0207 | H23: =-'CAPITAL DE TRABAJO'!$E$29/12 -> -1784.0207 | I23: =-'CAPITAL DE TRABAJO'!$E$29/12 -> -1784.0207 | ... M23: =-'CAPITAL DE TRABAJO'!$E$29/12 -> -1784.0207 | O23: =SUM(B23:M23) -> -21408.248
A24: (−) Impuesto a la Renta (MYPE Tributario 10%, provisión) | B24: =-MAX(0,$O$16-'CAPITAL DE TRABAJO'!$C$29)*0.1/12 -> -195.63494 | C24: =-MAX(0,$O$16-'CAPITAL DE TRABAJO'!$C$29)*0.1/12 -> -195.63494 | D24: =-MAX(0,$O$16-'CAPITAL DE TRABAJO'!$C$29)*0.1/12 -> -195.63494 | E24: =-MAX(0,$O$16-'CAPITAL DE TRABAJO'!$C$29)*0.1/12 -> -195.63494 | F24: =-MAX(0,$O$16-'CAPITAL DE TRABAJO'!$C$29)*0.1/12 -> -195.63494 | G24: =-MAX(0,$O$16-'CAPITAL DE TRABAJO'!$C$29)*0.1/12 -> -195.63494 | H24: =-MAX(0,$O$16-'CAPITAL DE TRABAJO'!$C$29)*0.1/12 -> -195.63494 | I24: =-MAX(0,$O$16-'CAPITAL DE TRABAJO'!$C$29)*0.1/12 -> -195.63494 | ... M24: =-MAX(0,$O$16-'CAPITAL DE TRABAJO'!$C$29)*0.1/12 -> -195.63494 | O24: =SUM(B24:M24) -> -2347.6193
A25: FLUJO OPERATIVO NETO DEL MES | B25: =B21+B22+B23+B24 -> -399.65563 | C25: =C21+C22+C23+C24 -> -399.65563 | D25: =D21+D22+D23+D24 -> -1172.1556 | E25: =E21+E22+E23+E24 -> -399.65563 | F25: =F21+F22+F23+F24 -> 1917.8444 | G25: =G21+G22+G23+G24 -> 2690.3444 | H25: =H21+H22+H23+H24 -> 5007.8444 | I25: =I21+I22+I23+I24 -> 4235.3444 | ... M25: =M21+M22+M23+M24 -> 5780.3444 | O25: =O21+O22+O23+O24 -> 31511.632
A26: (−) CAPEX Fase 2 (expansión de capacidad) | B26: =0 -> 0 | C26: =0 -> 0 | D26: =0 -> 0 | E26: =0 -> 0 | F26: =-INVERSION!$D$56 -> -34147.216 | G26: =0 -> 0 | H26: =0 -> 0 | I26: =0 -> 0 | J26: =0 -> 0 | K26: =0 -> 0 | L26: =0 -> 0 | M26: =0 -> 0 | O26: =SUM(B26:M26) -> -34147.216
A27: Saldo de caja inicial de operación (Nov 2026) | B27: =B36 -> 60322.319
A28: SALDO DE CAJA ACUMULADO (fin de mes) | B28: =B27+B25+B26 -> 59922.663 | C28: =B28+C25+C26 -> 59523.008 | D28: =C28+D25+D26 -> 58350.852 | E28: =D28+E25+E26 -> 57951.196 | F28: =E28+F25+F26 -> 25721.825 | G28: =F28+G25+G26 -> 28412.169 | H28: =G28+H25+H26 -> 33420.014 | I28: =H28+I25+I26 -> 37655.358 | J28: =I28+J25+J26 -> 43435.702 | ... M28: =L28+M25+M26 -> 57686.736
A30: MOMENTO 0 — INVERSIÓN Y FINANCIAMIENTO (Año 0: jul-oct 2026)
A31: Aporte de socios (ingreso de capital) | B31: ='CAPITAL DE TRABAJO'!B20 -> 89755.212
A32: Préstamo bancario (desembolso) | B32: ='CAPITAL DE TRABAJO'!B21 -> 40000
A33: (−) Inversión en activos (tangibles + intangibles) | B33: =-(INVERSION!D18+INVERSION!D36) -> -63832.893
A34: (−) Formalización (SUNARP) | B34: =-'CAPITAL DE TRABAJO'!B9 -> -800
A35: (−) Burn pre-operativo de importación (jul-oct) | B35: =-'CAPITAL DE TRABAJO'!B7 -> -4800
A36: (=) SALDO DE CAJA AL INICIAR OPERACIÓN (Nov 2026) | B36: =SUM(B31:B35) -> 60322.319
A38: Lectura ajustada: el flujo incorpora CAPEX de Fase 2, separa tributos recuperables del CAPEX económico y actualiza depreciación según vida útil técnica. La viabilidad se mantiene, pero con menor holgura: revisar VAN/TIR y caja mínima en RESUMEN FINANCIERO y CHECKS.
A41: D. FLUJO DE CAJA LIBRE Y EVALUACIÓN DE RENTABILIDAD (VAN / TIR) — HORIZONTE 3 AÑOS
A43: Tasa de descuento (COK) | B43: 0.2 | C43: Costo de oportunidad del capital (editable)
A44: Inflación anual de gastos fijos | B44: 0.025 | C44: BCRP (rango meta)
A45: Tasa de impuesto (MYPE Tributario) | B45: 0.1 | C45: SUNAT
A46: FLUJO DE CAJA LIBRE (económico, S/.) | B46: Año 0 | C46: Año 1 | D46: Año 2 | E46: Año 3
A47: Eventos del año | C47: ='PROYECCION DE VENTAS'!B19 -> 143 | D47: 180 | E47: 192
A48: Ingresos | C48: =O7 -> 167667.5 | D48: =D47*'PROYECCION DE VENTAS'!$B$3 -> 211050 | E48: =E47*'PROYECCION DE VENTAS'!$B$3 -> 225120
A49: (−) Costo variable | C49: =-O10 -> -57200 | D49: =-D47*'C. PRODUCCION'!$E$32 -> -72000 | E49: =-E47*'C. PRODUCCION'!$E$32 -> -76800
A50: (−) Gastos fijos (admin + ventas) | C50: =-(O11+O12) -> -55200 | D50: =C50*(1+$B$44) -> -56580 | E50: =D50*(1+$B$44) -> -57994.5
A51: (−) Depreciación y amortización | C51: =-O13 -> -20591.307 | D51: =C51 -> -20591.307 | E51: =D51 -> -20591.307
...

Sheet RESUMEN ECONOMICO
A1: RESUMEN ECONÓMICO - AÑO 1 (Escenario Realista)
A3: CONCEPTO | B3: VALOR (S/.)
A4: Total eventos Año 1 | B4: ='PROYECCION DE VENTAS'!B19 -> 143
A5: (+) Ingresos brutos | B5: ='FLUJO DE CAJA'!O7 -> 167667.5
A6: (- ) Costo variable total | B6: ='FLUJO DE CAJA'!O10 -> 57200 | C6: *
A7: (=) Margen bruto | B7: =B5-B6 -> 110467.5
A8: (-) Gastos administrativos (anual) | B8: ='FLUJO DE CAJA'!O11 -> 45600 | C8: *
A9: (-) Gastos de ventas (anual) | B9: ='FLUJO DE CAJA'!O12 -> 9600 | C9: *
A10: (-) Depreciación (anual) | B10: ='FLUJO DE CAJA'!O13 -> 20591.307 | C10: *
A11: TOTAL EGRESOS | B11: ='FLUJO DE CAJA'!O14 -> 132991.31 | C11: *
A12: (=) UTILIDAD OPERATIVA (EBIT) | B12: =B5-B11 -> 34676.193
A13: (−) Gastos financieros (intereses préstamo, Año 1) | B13: ='CAPITAL DE TRABAJO'!C29 -> 11200
A14: (=) UTILIDAD ANTES DE IMPUESTOS | B14: =B12-B13 -> 23476.193
A15: (−) Impuesto a la Renta (MYPE Tributario, 10%) | B15: =B14*0.1 -> 2347.6193
A16: UTILIDAD NETA DEL EJERCICIO | B16: =B14-B15 -> 21128.573
A18: EBITDA (caja operativa antes de deprec., deuda e impuestos) | B18: =B12+B10 -> 55267.5
A19: Nota: Utilidad neta positiva tras intereses e impuestos. El régimen MYPE Tributario se modela al 10% y los valores se actualizan desde Flujo de Caja, Capital de Trabajo e Inversión.

Sheet RESUMEN FINANCIERO
A1: INDICADORES FINANCIEROS CLAVE - AÑO 1
A3: MÉTRICA | B3: VALOR
A4: Inversión total modelada (inicial + CAPEX Fase 2) | B4: =INVERSION!D46+INVERSION!D56 -> 163902.43
A5: Ingresos anuales | B5: ='RESUMEN ECONOMICO'!B5 -> 167667.5
A6: Utilidad neta anual (después de intereses e IR) | B6: ='RESUMEN ECONOMICO'!B16 -> 21128.573
A7: Margen neto | B7: =B6/B5 -> 0.12601472
A8: ROI (sobre CAPEX) | B8: =B6/B4 -> 0.12890946
A9: Precio unitario por evento | B9: ='PROYECCION DE VENTAS'!B3 -> 1172.5
A10: Costo variable por evento (promedio ponderado) | B10: ='C. PRODUCCION'!E32 -> 400
A11: Margen de contribución por evento | B11: =B9-B10 -> 772.5
A12: Costos fijos + depreciación mensual | B12: ='GASTOS ADMINISTRATIVOS'!B8+'G. VENTAS'!B8+INVERSION!D51 -> 6315.9423
A13: PUNTO DE EQUILIBRIO (eventos por mes) | B13: =B12/B11 -> 8.1759771
A14: Saldo de caja acumulado fin de Año 1 (con servicio de deuda) | B14: ='FLUJO DE CAJA'!M28 -> 57686.736
A15: Saldo de caja mínimo del año (colchón de solvencia) | B15: =MIN('FLUJO DE CAJA'!B28:M28) -> 25721.825
A16: Servicio de deuda anual (cuota préstamo) | B16: ='CAPITAL DE TRABAJO'!E29 -> 21408.248
A17: EBITDA anual (caja operativa antes de deuda) | B17: ='RESUMEN ECONOMICO'!B7-'RESUMEN ECONOMICO'!B8-'RESUMEN ECONOMICO'!B9 -> 55267.5
A18: Punto de equilibrio de caja (incl. cuota préstamo, ev/mes) | B18: =('CAPITAL DE TRABAJO'!B4+'CAPITAL DE TRABAJO'!E29/12)/B11 -> 8.2641045
A19: VAN del proyecto (3 años, al COK) | B19: ='FLUJO DE CAJA'!B61 -> 24314.692
A20: TIR del proyecto (3 años) | B20: ='FLUJO DE CAJA'!B62 -> 0.28715973
A22: ANÁLISIS DE ESCENARIOS — AÑO 1 (variando el nivel de eventos)
A23: CONCEPTO | B23: PESIMISTA | C23: REALISTA | D23: OPTIMISTA
A24: Eventos en el año | B24: 110 | C24: ='PROYECCION DE VENTAS'!B19 -> 143 | D24: 175
A25: Ingresos | B25: =B24*'PROYECCION DE VENTAS'!$B$3 -> 128975 | C25: =C24*'PROYECCION DE VENTAS'!$B$3 -> 167667.5 | D25: =D24*'PROYECCION DE VENTAS'!$B$3 -> 205187.5
A26: Margen de contribución | B26: =B24*('PROYECCION DE VENTAS'!$B$3-'C. PRODUCCION'!$E$32) -> 84975 | C26: =C24*('PROYECCION DE VENTAS'!$B$3-'C. PRODUCCION'!$E$32) -> 110467.5 | D26: =D24*('PROYECCION DE VENTAS'!$B$3-'C. PRODUCCION'!$E$32) -> 135187.5
A27: (−) Gastos fijos + deprec. + intereses (anual) | B27: =-('CAPITAL DE TRABAJO'!$B$4*12+INVERSION!$D$51*12+'CAPITAL DE TRABAJO'!$C$29) -> -86991.307 | C27: =B27 -> -86991.307 | D27: =B27 -> -86991.307
A28: (=) Utilidad antes de impuestos | B28: =B26+B27 -> -2016.3074 | C28: =C26+C27 -> 23476.193 | D28: =D26+D27 -> 48196.193
A29: (−) Impuesto a la Renta (MYPE) | B29: =-MAX(0,B28)*0.1 -> 0 | C29: =-MAX(0,C28)*0.1 -> -2347.6193 | D29: =-MAX(0,D28)*0.1 -> -4819.6193
A30: (=) UTILIDAD NETA | B30: =B28+B29 -> -2016.3074 | C30: =C28+C29 -> 21128.573 | D30: =D28+D29 -> 43376.573
A31: Resultado | B31: =IF(B30>0,"Viable","Pérdida") -> Pérdida | C31: =IF(C30>0,"Viable","Pérdida") -> Viable | D31: =IF(D30>0,"Viable","Pérdida") -> Viable

Sheet COFACE
A1: RIESGO PAÍS, CLIMA DE NEGOCIOS Y SUPUESTOS MACROECONÓMICOS — PERÚ
A3: A. EVALUACIÓN DE RIESGO PAÍS Y CLIMA DE NEGOCIOS (COFACE)
A4: INDICADOR | B4: EVALUACIÓN | C4: FUENTE / NOTA
A5: Riesgo país (Perú) | B5: A4 – B (moderado a significativo) | C5: COFACE - verificar grado vigente: https://www.coface.com/news-economy-and-insights/business-risk-dashboard/country-risk-files/peru
A6: Clima de negocios (Perú) | B6: A4 (aceptable) | C6: COFACE - clima de negocios: https://www.coface.com/news-economy-and-insights/business-risk-dashboard/country-risk-files/peru
A7: Escala COFACE | B7: A1 (mín.) → A2 → A3 → A4 → B → C → D → E (máx.) | C7: Perú se ubica en el rango medio de la escala
A8: ¿Aplica a nuestro caso? | B8: SÍ | C8: Importamos desde China: el riesgo país y el tipo de cambio inciden directamente en costos
A10: B. SUPUESTOS MACROECONÓMICOS (fuentes oficiales — NO son de COFACE)
A11: VARIABLE | B11: VALOR | C11: FUENTE
A12: Tipo de cambio (S/. por USD) | B12: 3.386 | C12: SUNAT tipo de cambio: https://e-consulta.sunat.gob.pe/cl-at-ittipcam/tcS01Alias
A13: Inflación proyectada anual | B13: 0.025 | C13: BCRP reporte de inflación/rango meta: https://www.bcrp.gob.pe/publicaciones/reporte-de-inflacion.html
A14: IGV | B14: 0.18 | C14: SUNAT IGV: https://orientacion.sunat.gob.pe/3051-concepto-tasa-y-operaciones-gravadas-igv-empresas
A15: Régimen tributario | B15: MYPE Tributario (IR 10% hasta 15 UIT) | C15: SUNAT RMT: https://orientacion.sunat.gob.pe/3053-regimen-mype-tributario-rmt
A17: C. CONTEXTO SECTORIAL Y LECTURA PARA EL PROYECTO
A18: ASPECTO | B18: DETALLE
A19: Crecimiento del sector eventos | B19: ~18% anual (estimado de mercado / gremios; NO es dato COFACE)
A20: Fortaleza | B20: Alta demanda en Lima y provincias (bodas, graduaciones, corporativo premium)
A21: Riesgo clave | B21: Dependencia de importaciones y volatilidad del tipo de cambio
A22: Mitigación | B22: Importación por fases, margen de contribución amplio (S/.773/evento), proveedores ISO 9001
A23: CONCLUSIÓN | B23: Riesgo país moderado y clima aceptable; el modelo es viable y resiste shocks moderados de tipo de cambio

Sheet ANEXOS
A1: ANEXO 1: ACTIVOS OPERATIVOS Y COTIZACIONES (importación China)
A3: EQUIPO | B3: ESPECIFICACIÓN | C3: COTIZACIÓN (USD) | D3: PROVEEDOR / ORIGEN
A4: Plataforma giratoria 360° | B4: Motorizada, fibra de carbono, brazos estabilizadores | C4: 1200 | D4: Shenzhen
A5: Espejo Mágico / Tótem | B5: Pantalla táctil 55 pulgadas, impresión térmica | C5: 1500 | D5: Shenzhen
A6: Cabina LED Immersive | B6: Estructura inflable 2x2m, 500 LED, cromakey | C6: 1800 | D6: Guangzhou
A7: Audio-Guestbook | B7: Teléfono vintage modificado, subida a la nube | C7: 400 | D7: Yiwu
A8: Router Multi-Carrier | B8: Doble SIM, conectividad portátil en venue | C8: 210 | D8: Shenzhen
A9: Kit de contingencia Clase A | B9: Repuestos físicos críticos (fuentes, cables) | C9: 1300 | D9: Shenzhen
A11: Nota: Las cotizaciones FOB (Shenzhen/Guangzhou/Yiwu) de las 4 líneas principales son la FUENTE de costeo de la hoja G. EXPORT (DFI) y, vía ésta, de INVERSIÓN. El costo en soles se obtiene en la hoja COTIZACIONES (USD × tipo de cambio SUNAT).

Sheet COTIZACIONES
A1: ANEXO 2: DETALLE DE COTIZACIONES Y CONVERSIÓN A SOLES
A3: EQUIPO | B3: COTIZACIÓN USD | C3: TIPO DE CAMBIO | D3: COSTO EN S/.
A4: Plataforma 360° | B4: =ANEXOS!C4 -> 1200 | C4: =COFACE!$B$12 -> 3.386 | D4: =B4*C4 -> 4063.2
A5: Espejo Mágico / Tótem | B5: =ANEXOS!C5 -> 1500 | C5: =COFACE!$B$12 -> 3.386 | D5: =B5*C5 -> 5079
A6: Cabina LED | B6: =ANEXOS!C6 -> 1800 | C6: =COFACE!$B$12 -> 3.386 | D6: =B6*C6 -> 6094.8
A7: Audio-Guestbook | B7: =ANEXOS!C7 -> 400 | C7: =COFACE!$B$12 -> 3.386 | D7: =B7*C7 -> 1354.4
A8: TOTAL 4 LÍNEAS PRINCIPALES (FOB) | B8: =SUM(B4:B7) -> 4900 | D8: =SUM(D4:D7) -> 16591.4
A10: Nota: USD tomado del Anexo 1; tipo de cambio de la hoja COFACE (SUNAT). El FOB total alimenta el cálculo de CIF, tributos y DDP en la hoja G. EXPORT.

Sheet JUSTIFICACION
A1: BITACORA DE AJUSTES Y JUSTIFICACION - GLOBAL EVENT IMPORTS S.A.C.
A3: Área | B3: Concepto | C3: Ajuste realizado | D3: Justificación | E3: Impacto / fórmula | F3: Fuente / link
A4: SEGMENTACION | B4: Links de sustento | C4: Se reemplazaron referencias textuales por hipervínculos o URLs actuales. | D4: Evita fuentes muertas y permite auditoría externa del embudo. | E4: E4:E18 y E22:E26 | F4: https://m.inei.gob.pe/estadisticas/indice-tematico/poblacion-y-vivienda/ | https://www.gob.pe/institucion/inei/noticias/1087571-lima-supera-los-10-millones-400-mil-habitantes | https://apeim.com.pe/
A5: SEGMENTACION | B5: Población Lima | C5: Se actualizó Lima Metropolitana a 10,432,133 personas. | D5: Dato publicado por INEI/Gob.pe para Lima 2025. | E5: C5; B5 = C5/C4 | F5: https://www.gob.pe/institucion/inei/noticias/1087571-lima-supera-los-10-millones-400-mil-habitantes
A6: SEGMENTACION | B6: Participación requerida | C6: B17 ahora se calcula como ventas Año 1 / demanda insatisfecha. | D6: Evita hardcodear market share y mantiene coherencia con la proyección comercial. | E6: B17 = 'PROYECCION DE VENTAS'!B19/C16 | F6: Modelo interno
A7: G. EXPORT | B7: Tributos recuperables | C7: IGV, IPM y percepción se excluyen del factor capitalizable. | D7: Son desembolsos/cuentas recuperables, no costo económico permanente del activo. | E7: D46 = (D44-D48)/D17; D48 = D28+D29+D30 | F7: https://orientacion.sunat.gob.pe/3051-concepto-tasa-y-operaciones-gravadas-igv-empresas
A8: CAPITAL DE TRABAJO | B8: Crédito fiscal/percepción | C8: Se agregó como capital de trabajo recuperable. | D8: Mantiene la necesidad de caja sin inflar CAPEX/depreciación. | E8: B10 = 'G. EXPORT'!E48; B11 = SUM(B6:B10) | F8: Modelo interno / SUNAT
A9: INVERSION | B9: Vida útil | C9: Espejo pasa a 4 años y cabina LED a 3 años. | D9: Alineado con FICHA TECNICA: vida útil proyectada por producto. | E9: E6=4; E7=3 | F9: FICHA TECNICA!B12:E12
A10: INVERSION | B10: CAPEX Fase 2 | C10: Se estimó la expansión de Fase 2 con +1 plataforma, +2 espejos y +1 cabina. | D10: La capacidad sube a 16 eventos/mes desde marzo; antes no había CAPEX asociado. | E10: D56 = D5+2*D6+D7 | F10: INVERSION!A56:B56
A11: FLUJO DE CAJA | B11: Desembolso Fase 2 | C11: Se agregó fila 26 con CAPEX Fase 2 en marzo 2027. | D11: La expansión autofinanciada debe afectar caja y evaluación de rentabilidad. | E11: F26 = -INVERSION!D56 | F11: Modelo interno
A12: FLUJO DE CAJA | B12: VAN/TIR | C12: El FCL Año 1 incluye CAPEX Fase 2. | D12: La evaluación refleja la inversión necesaria para sostener capacidad futura. | E12: C58 = C54+C55+C56 | F12: Modelo interno
A13: CAPITAL DE TRABAJO | B13: Aporte por socio | C13: Se corrigió divisor de 3 a 6 fundadores. | D13: La hoja indica aporte de socios (6 fundadores); el cálculo anterior decía ÷3. | E13: B23 = B20/6 | F13: CARATULA / CAPITAL DE TRABAJO

Sheet CHECKS
A1: CHECKS DEL MODELO FINANCIERO
A3: Check | B3: Actual | C3: Esperado | D3: Diferencia | E3: Tolerancia | F3: Estado | G3: Notas / ubicación
A4: Eventos meta = proyección ventas | B4: =SEGMENTACION!C18 -> 143 | C4: ='PROYECCION DE VENTAS'!B19 -> 143 | D4: =B4-C4 -> 0 | E4: 0.01 | F4: =IF(ABS(D4)<=E4,"OK","REVISAR") -> OK | G4: SEGMENTACION C18 vs PROYECCION DE VENTAS B19
A5: Mix de paquetes suma 100% | B5: ='PROYECCION DE VENTAS'!D33 -> 1 | C5: =1 -> 1 | D5: =B5-C5 -> 0 | E5: 0.001 | F5: =IF(ABS(D5)<=E5,"OK","REVISAR") -> OK | G5: PROYECCION DE VENTAS D33
A6: CAPEX Fase 2 identificado | B6: =INVERSION!D56 -> 34147.216 | C6: =0 -> 0 | D6: =B6-C6 -> 34147.216 | E6: 0 | F6: =IF(B6>0,"OK","REVISAR") -> OK | G6: INVERSION D56
A7: CAPEX Fase 2 incluido en FCL Año 1 | B7: =-'FLUJO DE CAJA'!C56 -> 34147.216 | C7: =INVERSION!D56 -> 34147.216 | D7: =B7-C7 -> 0 | E7: 0.01 | F7: =IF(ABS(D7)<=E7,"OK","REVISAR") -> OK | G7: FLUJO DE CAJA C56
A8: Capital de trabajo recuperado al cierre | B8: ='FLUJO DE CAJA'!E57 -> 65922.319 | C8: ='CAPITAL DE TRABAJO'!B11 -> 65922.319 | D8: =B8-C8 -> 0 | E8: 0.01 | F8: =IF(ABS(D8)<=E8,"OK","REVISAR") -> OK | G8: FLUJO DE CAJA E57 vs CAPITAL DE TRABAJO B11
A9: Factor neto excluye tributos recuperables | B9: ='G. EXPORT'!D46 -> 1.6808041 | C9: =('G. EXPORT'!D44-'G. EXPORT'!D48)/'G. EXPORT'!D17 -> 1.6808041 | D9: =B9-C9 -> 0 | E9: 0.0001 | F9: =IF(ABS(D9)<=E9,"OK","REVISAR") -> OK | G9: G. EXPORT D46
A10: Vidas útiles importadas alineadas | B10: =SUM(INVERSION!E5:E8) -> 17 | C10: =17 -> 17 | D10: =B10-C10 -> 0 | E10: 0.01 | F10: =IF(ABS(D10)<=E10,"OK","REVISAR") -> OK | G10: INVERSION E5:E8 = 5+4+3+5
A11: VAN positivo | B11: ='FLUJO DE CAJA'!B61 -> 24314.692 | C11: =0 -> 0 | D11: =B11-C11 -> 24314.692 | E11: 0 | F11: =IF(B11>0,"OK","REVISAR") -> OK | G11: FLUJO DE CAJA B61
A12: TIR > COK | B12: ='FLUJO DE CAJA'!B62 -> 0.28715973 | C12: ='FLUJO DE CAJA'!B43 -> 0.2 | D12: =B12-C12 -> 0.087159729 | E12: 0 | F12: =IF(B12>C12,"OK","REVISAR") -> OK | G12: FLUJO DE CAJA B62 vs B43
A13: Caja mínima positiva | B13: ='RESUMEN FINANCIERO'!B15 -> 25721.825 | C13: =0 -> 0 | D13: =B13-C13 -> 25721.825 | E13: 0 | F13: =IF(B13>0,"OK","REVISAR") -> OK | G13: RESUMEN FINANCIERO B15
